Traceback (most recent call last):
  File "/Users/seanwalsh/Documents/Github-Mac-Laptop/philstatsbook/.venv/lib/python3.12/site-packages/jupyter_cache/executors/utils.py", line 58, in single_nb_execution
    executenb(
  File "/Users/seanwalsh/Documents/Github-Mac-Laptop/philstatsbook/.venv/lib/python3.12/site-packages/nbclient/client.py", line 1314, in execute
    return NotebookClient(nb=nb, resources=resources, km=km, **kwargs).execute()
           ^^^^^^^^^^^^^^^^^^^^^^^^^^^^^^^^^^^^^^^^^^^^^^^^^^^^^^^^^^^^^^^^^^^^^
  File "/Users/seanwalsh/Documents/Github-Mac-Laptop/philstatsbook/.venv/lib/python3.12/site-packages/jupyter_core/utils/__init__.py", line 165, in wrapped
    return loop.run_until_complete(inner)
           ^^^^^^^^^^^^^^^^^^^^^^^^^^^^^^
  File "/Library/Frameworks/Python.framework/Versions/3.12/lib/python3.12/asyncio/base_events.py", line 664, in run_until_complete
    return future.result()
           ^^^^^^^^^^^^^^^
  File "/Users/seanwalsh/Documents/Github-Mac-Laptop/philstatsbook/.venv/lib/python3.12/site-packages/nbclient/client.py", line 709, in async_execute
    await self.async_execute_cell(
  File "/Users/seanwalsh/Documents/Github-Mac-Laptop/philstatsbook/.venv/lib/python3.12/site-packages/nbclient/client.py", line 1062, in async_execute_cell
    await self._check_raise_for_error(cell, cell_index, exec_reply)
  File "/Users/seanwalsh/Documents/Github-Mac-Laptop/philstatsbook/.venv/lib/python3.12/site-packages/nbclient/client.py", line 918, in _check_raise_for_error
    raise CellExecutionError.from_cell_and_msg(cell, exec_reply_content)
nbclient.exceptions.CellExecutionError: An error occurred while executing the following cell:
------------------
uniform_visual(2)
uniform_visual(5)
uniform_visual(10)
------------------


[0;31m---------------------------------------------------------------------------[0m
[0;31mNameError[0m                                 Traceback (most recent call last)
Cell [0;32mIn[3], line 1[0m
[0;32m----> 1[0m [43muniform_visual[49m[43m([49m[38;5;241;43m2[39;49m[43m)[49m
[1;32m      2[0m uniform_visual([38;5;241m5[39m)
[1;32m      3[0m uniform_visual([38;5;241m10[39m)

Cell [0;32mIn[2], line 6[0m, in [0;36muniform_visual[0;34m(n)[0m
[1;32m      3[0m m [38;5;241m=[39m n[38;5;241m-[39m[38;5;241m1[39m
[1;32m      5[0m v [38;5;241m=[39m np[38;5;241m.[39marange([38;5;241m0[39m,n) [38;5;66;03m# values for x-axis[39;00m
[0;32m----> 6[0m Xpdf [38;5;241m=[39m [43mrandint[49m[38;5;241m.[39mpmf(v, [38;5;241m0[39m,n) [38;5;66;03m# pdf for X [39;00m
[1;32m      7[0m                     [38;5;66;03m# it is a_1+n_1 since python programs {a_1, a_1+1, . . . , b_1} in terms of a_1 and b_1+1[39;00m
[1;32m      8[0m Xcdf [38;5;241m=[39m randint[38;5;241m.[39mcdf(v, [38;5;241m0[39m, n) [38;5;66;03m# cdf for X[39;00m

[0;31mNameError[0m: name 'randint' is not defined

